Workbook

Sheet 見積書
B2: 御 見 積 書
E3: 見積日:
E4: 見積No:
B6: お客様名: | E6: カトモーター
B7: 〒
B8: ご住所:
B9: TEL:
B11: お見積り金額 | D11: =F61
B13: No. | C13: 項目 | D13: 数量 | E13: 単価 | F13: 金額
B14: 【車両本体】
B15: 1 | D15: 1 | E15: =IFERROR(VLOOKUP(C15,データ!$A$3:$F$100,6,FALSE),0) | F15: =D15*E15
B17: 【オプション装備】
B18: 2 | E18: =IFERROR(VLOOKUP(C18,データ!$M$3:$O$200,3,FALSE),0) | F18: =IF(D18="",0,D18*E18)
B19: 3 | E19: =IFERROR(VLOOKUP(C19,データ!$M$3:$O$200,3,FALSE),0) | F19: =IF(D19="",0,D19*E19)
B20: 4 | E20: =IFERROR(VLOOKUP(C20,データ!$M$3:$O$200,3,FALSE),0) | F20: =IF(D20="",0,D20*E20)
B21: 5 | E21: =IFERROR(VLOOKUP(C21,データ!$M$3:$O$200,3,FALSE),0) | F21: =IF(D21="",0,D21*E21)
B22: 6 | E22: =IFERROR(VLOOKUP(C22,データ!$M$3:$O$200,3,FALSE),0) | F22: =IF(D22="",0,D22*E22)
B23: 7 | E23: =IFERROR(VLOOKUP(C23,データ!$M$3:$O$200,3,FALSE),0) | F23: =IF(D23="",0,D23*E23)
B24: 8 | E24: =IFERROR(VLOOKUP(C24,データ!$M$3:$O$200,3,FALSE),0) | F24: =IF(D24="",0,D24*E24)
B25: 9 | E25: =IFERROR(VLOOKUP(C25,データ!$M$3:$O$200,3,FALSE),0) | F25: =IF(D25="",0,D25*E25)
B26: 10 | E26: =IFERROR(VLOOKUP(C26,データ!$M$3:$O$200,3,FALSE),0) | F26: =IF(D26="",0,D26*E26)
B27: 11 | E27: =IFERROR(VLOOKUP(C27,データ!$M$3:$O$200,3,FALSE),0) | F27: =IF(D27="",0,D27*E27)
B28: 12 | E28: =IFERROR(VLOOKUP(C28,データ!$M$3:$O$200,3,FALSE),0) | F28: =IF(D28="",0,D28*E28)
B29: 13 | E29: =IFERROR(VLOOKUP(C29,データ!$M$3:$O$200,3,FALSE),0) | F29: =IF(D29="",0,D29*E29)
... B37: 21 | E37: =IFERROR(VLOOKUP(C37,データ!$M$3:$O$200,3,FALSE),0) | F37: =IF(D37="",0,D37*E37)
B38: オプション小計 | F38: =SUM(F18:F37)
B40: 【税金・諸費用】
C41: 環境性能割 | F41: =IFERROR(VLOOKUP(C15,データ!$A$3:$G$100,7,FALSE),0)
C42: 重量税 | F42: =IFERROR(VLOOKUP(C15,データ!$A$3:$H$100,8,FALSE),0)
C43: 自賠責保険 | F43: =IFERROR(VLOOKUP(C15,データ!$A$3:$I$100,9,FALSE),0)
C44: 登録代行手数料 | F44: 35000
C45: 車庫証明代行手数料 | F45: 15000
C46: 納車費用 | F46: 0
C47: 下取り手数料 | F47: 0
C48: リサイクル料金 | F48: 12000
B49: 諸費用小計 | F49: =SUM(F41:F48)
B52: 【下取り・値引き】
C53: 下取り車 | F53: 0
C54: 下取り価格 | F54: 0
C55: 値引き | F55: 0
...

Sheet データ
A1: 【車両マスタ】 | L1: 【オプションマスタ】 | Q1: 【諸費用マスタ】
A2: 車両名 | B2: ベース車 | C2: 駆動 | D2: 排気量 | E2: 燃料 | F2: 販売価格 | G2: 環境性能割 | H2: 重量税 | I2: 自賠責 | L2: コード | M2: オプション名 | N2: カテゴリ | O2: 価格 | Q2: 費用名 | R2: 金額
A3: keymaker ［ｷｰﾒｲｶｰ］ | B3: ｷｬﾝﾋﾟﾝｸﾞﾄﾚｰﾗｰ ﾍﾞｰｽ KNOTT製 | C3: この欄とＯＰ消して見積 | E3: - | F3: 3528000 | G3: 106000 | H3: 8200 | I3: 5440 | L3: 152 | M3: 雪国断熱仕様 天井、床、壁内 | N3: 一般 | Q3: 登録代行手数料 | R3: 35000
A4: sweep [ｽｲｰﾌﾟ] | B4: ﾀｳﾝｴｰｽ ＧＬ 2ＷＤ | C4: 2ＷＤ ＡＴ | D4: 1500 | E4: ｶﾞｿﾘﾝ | F4: 4007000 | G4: 50600 | H4: 16400 | I4: 20580 | L4: 102 | M4: フロントオーバーヘッドシェルフ | N4: 一般 | Q4: 車庫証明代行手数料 | R4: 15000
A5: sweep [ｽｲｰﾌﾟ] | B5: ﾀｳﾝｴｰｽ ＧＬ 4ＷＤ | C5: 4ＷＤ ＡＴ | D5: 1500 | E5: ｶﾞｿﾘﾝ | F5: 4208000 | G5: 57600 | H5: 16400 | I5: 20580 | L5: 103 | M5: 室内カーテン | N5: 一般 | Q5: 納車費用 | R5: 0
A6: ﾅﾛｰﾛﾝｸﾞﾄﾚｲﾝ ﾊｲｴｰｽ | B6: 標準ﾎﾞﾃﾞｨｰ ﾛﾝｸﾞ ﾊｲﾙｰﾌDX・GLﾊﾟｯｹｰｼﾞ2000G 2WD | C6: 2ＷＤ ＡＴ | D6: 2000 | E6: ｶﾞｿﾘﾝ | F6: 5663000 | G6: 70000 | H6: 24600 | I6: 20580 | L6: 104 | M6: 下回り一部 塩害防止塗装(タイヤハウス及び一部不適合) | N6: 一般 | Q6: 下取り手数料 | R6: 15000
A7: ﾅﾛｰﾛﾝｸﾞﾄﾚｲﾝ ﾊｲｴｰｽ | B7: 標準ﾎﾞﾃﾞｨｰ ﾛﾝｸﾞ ﾊｲﾙｰﾌDX・GLﾊﾟｯｹｰｼﾞ2800D 4WD | C7: 4ＷＤ ＡＴ | E7: 軽油 | F7: 6483000 | G7: 92000 | H7: 24600 | I7: 20580 | L7: 183 | M7: 天井 センターウッド＆ドームライト仕様 | N7: 一般 | Q7: リサイクル料金 | R7: 12000
A8: ロングトレイン ﾊｲｴｰｽ | B8: ﾜｲﾄﾞﾛﾝｸﾞﾐﾄﾞﾙﾙｰﾌ 2700G 2WD ﾜｺﾞﾝGL | C8: 2ＷＤ ＡＴ | D8: 2700 | E8: ｶﾞｿﾘﾝ | F8: 6143000 | G8: 84000 | H8: 24600 | I8: 20580 | L8: 184 | M8: 天井 ワイドセンターウッド＆ダウンライト仕様（純正天井内張使用車不適合） | N8: 一般
A9: ロングトレイン ﾊｲｴｰｽ | B9: ﾜｲﾄﾞﾛﾝｸﾞﾐﾄﾞﾙﾙｰﾌ 2700G 4WD ﾜｺﾞﾝGL | C9: 4ＷＤ ＡＴ | D9: 2700 | E9: ｶﾞｿﾘﾝ | F9: 6423000 | G9: 88000 | H9: 24600 | I9: 20580 | L9: 185 | M9: 天井 ワイドセンターウッド＆ダウンライト仕様（純正天井内張使用車不適合） | N9: 一般 | O9: 200000
A10: ロングトレイン ﾊｲｴｰｽ | B10: ﾜｲﾄﾞﾛﾝｸﾞ2700G 2WD ｼﾞｪﾝﾄﾘｰﾙｰﾌ ﾜｺﾞﾝGL | C10: 2ＷＤ ＡＴ | D10: 2700 | E10: ｶﾞｿﾘﾝ | F10: 7023000 | G10: 84000 | H10: 24600 | I10: 20580 | L10: 400 | M10: お持込み車キャンピング 解体費用 | N10: 一般 | O10: 150000
A11: ロングトレイン ﾊｲｴｰｽ | B11: ﾜｲﾄﾞﾛﾝｸﾞ2700G 4WD ｼﾞｪﾝﾄﾘｰﾙｰﾌ ﾜｺﾞﾝGL | C11: 4ＷＤ ＡＴ | D11: 2700 | E11: ｶﾞｿﾘﾝ | F11: 7303000 | G11: 88000 | H11: 24600 | I11: 20580 | L11: 401 | M11: 車検整備点検料 | N11: 一般 | O11: 50000
A12: ブルームーンEX ﾊｲｴｰｽ | B12: ﾜｲﾄﾞｽｰﾊﾟｰﾛﾝｸﾞDX・GLﾊﾟｯｹｰｼﾞ2700G 2WD | C12: 2ＷＤ ＡＴ | D12: 2700 | E12: ｶﾞｿﾘﾝ | F12: 6493000 | G12: 75000 | H12: 24600 | I12: 20580 | L12: 500 | M12: 中古車 エンジン足回り点検整備一式 | N12: 一般 | O12: 50000
A13: ブルームーンEX ﾊｲｴｰｽ | B13: ﾜｲﾄﾞｽｰﾊﾟｰﾛﾝｸﾞDX・GLﾊﾟｯｹｰｼﾞ2700G 4WD | C13: 4ＷＤ ＡＴ | D13: 2700 | E13: ｶﾞｿﾘﾝ | F13: 6773000 | G13: 83000 | H13: 24600 | I13: 20580 | L13: 106 | M13: ﾌｧﾝﾀｽﾃｨｯｸﾙｰﾌﾍﾞﾝﾁﾚｰﾀｰ ｵﾘｼﾞﾅﾙﾍﾞﾝﾁﾚｰﾀｰｺﾝﾄﾛｰﾗｰ付き | N13: 外装 | O13: 80000
A14: ブルームーンEX ﾊｲｴｰｽ | B14: ﾜｲﾄﾞｽｰﾊﾟｰﾛﾝｸﾞDX・GLﾊﾟｯｹｰｼﾞ2800DT 2WD | C14: 2ＷＤ ＡＴ | D14: 2800 | E14: 軽油 | F14: 6933000 | G14: 87000 | H14: 24600 | I14: 20580 | L14: 107 | M14: ルーフベンチレーター （ ＭＡＸファン ） | N14: 外装 | O14: 85000
A15: ブルームーンEX ﾊｲｴｰｽ | B15: ﾜｲﾄﾞｽｰﾊﾟｰﾛﾝｸﾞDX・GLﾊﾟｯｹｰｼﾞ2800DT 4WD | C15: 4ＷＤ ＡＴ | D15: 2800 | E15: 軽油 | F15: 7213000 | G15: 95000 | H15: 24600 | I15: 20580 | L15: 108 | M15: ルーフベンチレーター （ ＭＡＸファン リモコンモデル ） | N15: 外装 | O15: 95000
A16: ブルームーンEX ﾊｲｴｰｽ | B16: ﾜｲﾄﾞｽｰﾊﾟｰﾛﾝｸﾞ 特装2700G 2WD | C16: 2ＷＤ ＡＴ | D16: 2700 | E16: ｶﾞｿﾘﾝ | F16: 6773000 | G16: 80000 | H16: 24600 | I16: 20580 | L16: 109 | M16: サイドオーニング 3.0ｍ | N16: 外装 | O16: 165000
A17: ブルームーンEX ﾊｲｴｰｽ | B17: ﾜｲﾄﾞｽｰﾊﾟｰﾛﾝｸﾞ 特装2700G 4WD | C17: 4ＷＤ ＡＴ | D17: 2700 | E17: ｶﾞｿﾘﾝ | F17: 7053000 | G17: 88000 | H17: 24600 | I17: 20580 | L17: 110 | M17: サイドオーニング 3.5ｍ | N17: 外装 | O17: 180000
A18: ブルームーンEX ﾊｲｴｰｽ | B18: ﾜｲﾄﾞｽｰﾊﾟｰﾛﾝｸﾞ 特装2800DT 2WD | C18: 2ＷＤ ＡＴ | D18: 2800 | E18: 軽油 | F18: 7213000 | G18: 87000 | H18: 24600 | I18: 20580 | L18: 136 | M18: サイクルキャリア | N18: 外装 | O18: 88000
A19: ブルームーンEX ﾊｲｴｰｽ | B19: ﾜｲﾄﾞｽｰﾊﾟｰﾛﾝｸﾞ 特装2800DT 4WD | C19: 4ＷＤ ＡＴ | D19: 2800 | E19: 軽油 | F19: 7493000 | G19: 95000 | H19: 24600 | I19: 20580 | L19: 170 | M19: カー網戸1枚 | N19: 外装 | O19: 14000
A20: ブルームーンEX ﾊｲｴｰｽ | B20: ﾜｲﾄﾞｽｰﾊﾟｰﾛﾝｸﾞ ﾜｺﾞﾝｸﾞﾗﾝﾄﾞｷｬﾋﾞﾝ 2700G 2WD | C20: 2ＷＤ ＡＴ | D20: 2700 | E20: ｶﾞｿﾘﾝ | F20: 7623000 | G20: 97000 | H20: 24600 | I20: 20580 | L20: 171 | M20: カー網戸２枚 | N20: 外装 | O20: 28000
A21: ブルームーンEX ﾊｲｴｰｽ | B21: ﾜｲﾄﾞｽｰﾊﾟｰﾛﾝｸﾞ ﾜｺﾞﾝｸﾞﾗﾝﾄﾞｷｬﾋﾞﾝ 2700G 4WD | C21: 4ＷＤ ＡＴ | D21: 2700 | E21: ｶﾞｿﾘﾝ | F21: 7903000 | G21: 110000 | H21: 24600 | I21: 20580 | L21: 172 | M21: カー網戸３枚 | N21: 外装 | O21: 42000
A22: シェスタ ﾊｲｴｰｽ | B22: ﾜｲﾄﾞｽｰﾊﾟｰﾛﾝｸﾞDX・GLﾊﾟｯｹｰｼﾞ2700G 2WD | C22: 2ＷＤ ＡＴ | D22: 2700 | E22: ｶﾞｿﾘﾝ | F22: 6343000 | G22: 75000 | H22: 24600 | I22: 20580 | L22: 173 | M22: ｵﾘｼﾞﾅﾙﾅﾝﾊﾞｰﾌﾚｰﾑ前後 katomotorﾗｳﾝﾄﾞｽﾃｯｶｰ前＆家具ｽﾃｯｶｰ | N22: 外装
A23: シェスタ ﾊｲｴｰｽ | B23: ﾜｲﾄﾞｽｰﾊﾟｰﾛﾝｸﾞDX・GLﾊﾟｯｹｰｼﾞ2700G 4WD | C23: 4ＷＤ ＡＴ | D23: 2700 | E23: ｶﾞｿﾘﾝ | F23: 6623000 | G23: 83000 | H23: 24600 | I23: 20580 | L23: 177 | M23: Ｋエンブレム １か所 | N23: 外装 | O23: 8000
A24: シェスタ ﾊｲｴｰｽ | B24: ﾜｲﾄﾞｽｰﾊﾟｰﾛﾝｸﾞDX・GLﾊﾟｯｹｰｼﾞ2800DT 2WD | C24: 2ＷＤ ＡＴ | D24: 2800 | E24: 軽油 | F24: 6783000 | G24: 87000 | H24: 24600 | I24: 20580 | L24: 178 | M24: Ｋエンブレム ２か所 | N24: 外装 | O24: 16000
A25: シェスタ ﾊｲｴｰｽ | B25: ﾜｲﾄﾞｽｰﾊﾟｰﾛﾝｸﾞDX・GLﾊﾟｯｹｰｼﾞ2800DT 4WD | C25: 4ＷＤ ＡＴ | D25: 2800 | E25: 軽油 | F25: 7063000 | G25: 95000 | H25: 24600 | I25: 20580 | L25: 179 | M25: リフトアップスプリング＆ショックアブソーバー | N25: 外装 | O25: 235000
A26: シェスタ ﾊｲｴｰｽ | B26: ﾜｲﾄﾞｽｰﾊﾟｰﾛﾝｸﾞ 特装2700G 2WD | C26: 2ＷＤ ＡＴ | D26: 2700 | E26: ｶﾞｿﾘﾝ | F26: 6623000 | G26: 80000 | H26: 24600 | I26: 20580 | L26: 330 | M26: ボディーコーティング | N26: 外装 | O26: 120000
A27: シェスタ ﾊｲｴｰｽ | B27: ﾜｲﾄﾞｽｰﾊﾟｰﾛﾝｸﾞ 特装2700G 4WD | C27: 4ＷＤ ＡＴ | D27: 2700 | E27: ｶﾞｿﾘﾝ | F27: 6903000 | G27: 88000 | H27: 24600 | I27: 20580 | L27: 331 | M27: ボディーコーティング ＤＤ | N27: 外装 | O27: 140000
A28: シェスタ ﾊｲｴｰｽ | B28: ﾜｲﾄﾞｽｰﾊﾟｰﾛﾝｸﾞ 特装2800DT 2WD | C28: 2ＷＤ ＡＴ | D28: 2800 | E28: 軽油 | F28: 7063000 | G28: 87000 | H28: 24600 | I28: 20580 | L28: 332 | M28: 下回り防錆処理 | N28: 外装 | O28: 140000
A29: シェスタ ﾊｲｴｰｽ | B29: ﾜｲﾄﾞｽｰﾊﾟｰﾛﾝｸﾞ 特装2800DT 4WD | C29: 4ＷＤ ＡＴ | D29: 2800 | E29: 軽油 | F29: 7343000 | G29: 95000 | H29: 24600 | I29: 20580 | L29: 333 | M29: スタッドレスタイヤ＆アルミホイール ﾊｲｴｰｽ BS VL10 195/80R15 107/105 | N29: 外装 | O29: 209000
A30: シェスタ ﾊｲｴｰｽ | B30: ﾜｲﾄﾞｽｰﾊﾟｰﾛﾝｸﾞ ﾜｺﾞﾝｸﾞﾗﾝﾄﾞｷｬﾋﾞﾝ 2700G 2WD | C30: 2ＷＤ ＡＴ | D30: 2700 | E30: ｶﾞｿﾘﾝ | F30: 7123000 | G30: 97000 | H30: 24600 | I30: 20580 | L30: 334 | M30: スタッドレスタイヤ＆アルミホイール ﾀｳﾝｴｰｽ BS VL10A 165/80 R14 97/95N | N30: 外装 | O30: 151000
A31: シェスタ ﾊｲｴｰｽ | B31: ﾜｲﾄﾞｽｰﾊﾟｰﾛﾝｸﾞ ﾜｺﾞﾝｸﾞﾗﾝﾄﾞｷｬﾋﾞﾝ 2700G 4WD | C31: 4ＷＤ ＡＴ | D31: 2700 | E31: ｶﾞｿﾘﾝ | F31: 7403000 | G31: 110000 | H31: 24600 | I31: 20580 | L31: 336 | M31: タウンエース サイド裾ツートンステッカー | N31: 外装 | O31: 40000
A32: TIPTOP [ﾁｯﾌﾟﾄｯﾌﾟ] ﾊｲｴｰｽ | B32: ﾜｲﾄﾞﾛﾝｸﾞ2700G 2WD ワゴンGL | C32: 2ＷＤ ＡＴ | D32: 2700 | E32: ｶﾞｿﾘﾝ | F32: 7983000 | G32: 84000 | H32: 24600 | I32: 20580 | L32: 111 | M32: ＦＦヒーター ﾍﾞﾊﾞｽﾄ | N32: 電装 | O32: 250000
A33: TIPTOP [ﾁｯﾌﾟﾄｯﾌﾟ] ﾊｲｴｰｽ | B33: ﾜｲﾄﾞﾛﾝｸﾞ2700G 4WD ワゴンGL | C33: 4ＷＤ ＡＴ | D33: 2700 | E33: ｶﾞｿﾘﾝ | F33: 8263000 | G33: 88000 | H33: 24600 | I33: 20580 | L33: 112 | M33: ＦＦヒーター ﾍﾞﾊﾞｽﾄ | N33: 電装 | O33: 250000
A34: PABLO [ﾊﾟﾌﾞﾛ] ﾊｲｴｰｽ | B34: ﾜｲﾄﾞﾛﾝｸﾞ2700G 2WD ワゴンGL | C34: 2ＷＤ ＡＴ | D34: 2700 | E34: ｶﾞｿﾘﾝ | F34: 8883000 | G34: 84000 | H34: 24600 | I34: 20580 | L34: 119 | M34: 高性能ｻｲﾝ波300Ｗｲﾝﾊﾞｰﾀｰ 自動切替ﾘﾚｰ付 | N34: 電装 | O34: 65000
... A36: ＬＩＢ [ﾅﾛｰリブ] ﾊｲｴｰｽ | B36: 標準ﾎﾞﾃﾞｨｰ ﾛﾝｸﾞ ﾊｲﾙｰﾌDX・GLﾊﾟｯｹｰｼﾞ2000G 2WD | C36: 2ＷＤ ＡＴ | D36: 2000 | E36: ｶﾞｿﾘﾝ | F36: 5913000 | G36: 70000 | H36: 24600 | I36: 20580 | L36: 121 | M36: ＡＧＭﾃﾞｨｰﾌﾟｻｲｸﾙﾊﾞｯﾃﾘｰ100Aｈ １台追加 計２台 | N36: 電装 | O36: 50000
A37: ＬＩＢ [ﾅﾛｰリブ] ﾊｲｴｰｽ | B37: 標準ﾎﾞﾃﾞｨｰ ﾛﾝｸﾞ ﾊｲﾙｰﾌDX・GLﾊﾟｯｹｰｼﾞ2800D 4WD | C37: 4ＷＤ ＡＴ | E37: 軽油 | F37: 6733000 | G37: 92000 | H37: 24600 | I37: 20580 | L37: 122 | M37: ＡＧＭﾃﾞｨｰﾌﾟｻｲｸﾙﾊﾞｯﾃﾘｰ100Aｈ ２台追加 計３台 | N37: 電装 | O37: 100000
A38: ＬＩＢ [リブ] ﾊｲｴｰｽ | B38: ﾜｲﾄﾞﾛﾝｸﾞ2700G 2WD ワゴンGL | C38: 2ＷＤ ＡＴ | D38: 2700 | E38: ｶﾞｿﾘﾝ | F38: 6393000 | G38: 84000 | H38: 24600 | I38: 20580 | L38: 123 | M38: ＡＧＭﾃﾞｨｰﾌﾟｻｲｸﾙﾊﾞｯﾃﾘｰ100Aｈ ３台追加 計４台 | N38: 電装 | O38: 150000
A39: ＬＩＢ [リブ] ﾊｲｴｰｽ | B39: ﾜｲﾄﾞﾛﾝｸﾞ2700G 4WD ワゴンGL | C39: 4ＷＤ ＡＴ | D39: 2700 | E39: ｶﾞｿﾘﾝ | F39: 6673000 | G39: 88000 | H39: 24600 | I39: 20580 | L39: 134 | M39: 充電ｼｽﾃﾑ3WAY ﾊﾞｯﾃﾘｰﾁｬｰｼﾞｬｰｺﾝﾄﾛｰﾗｰﾍﾟﾘｰくん | N39: 電装 | O39: 80000
A40: KLEIN [ｸﾗｲﾝ] ﾊｲｴｰｽ | B40: 標準ﾎﾞﾃﾞｨｰ ﾛﾝｸﾞ ﾊｲﾙｰﾌDX・GLﾊﾟｯｹｰｼﾞ2000G 2WD | C40: 2ＷＤ ＡＴ | D40: 2000 | E40: ｶﾞｿﾘﾝ | F40: 6163000 | G40: 70000 | H40: 24600 | I40: 20580 | L40: 135 | M40: ソーラー充電システム 180W | N40: 電装 | O40: 185000
A41: KLEIN [ｸﾗｲﾝ] ﾊｲｴｰｽ | B41: 標準ﾎﾞﾃﾞｨｰ ﾛﾝｸﾞ ﾊｲﾙｰﾌDX・GLﾊﾟｯｹｰｼﾞ2800D 4WD | C41: 4ＷＤ ＡＴ | E41: 軽油 | F41: 6983000 | G41: 92000 | H41: 24600 | I41: 20580 | L41: 147 | M41: 電子レンジ（家具製作あり） | N41: 電装 | O41: 43000
...
